Workbook
Name Slicer_Months__TANGGAL_SHARE_ORDER1: #N/A
Name Slicer_NAMA_PEKERJAAN1: #N/A
Name Slicer_NAMA_PEKERJAAN2: #N/A
Name Slicer_TANGGAL: #N/A

Sheet DASHBOARD
AE3: 1 | AH3: 2 | AV3: 6

Sheet DATA CASH
A1: CATATAN KEUANGAN PROJECT
A2: SALDO MASUK | C2: SALDO KELUAR
A3: =SUMIFS(Table3[CATATAN KAS],Table3[JENIS DATA],"KAS MASUK") -> 3.817364e+08 | C3: =SUMIFS(Table3[CATATAN KAS],Table3[JENIS DATA],"KAS KELUAR") -> 381891257
A4: SISA SALDO
A5: =A3-C3 -> -154857.4
A6: TANGGAL | B6: KETERANGAN | C6: JENIS DATA | D6: CATATAN KAS
A7: 46029 | B7: PEMBAYARAN WIFI PERIODE JANUARI | C7: KAS KELUAR | D7: 263850 | F7: Sum of CATATAN KAS | G7: Column Labels
A8: 46037 | B8: DP MANDOR JNP037 | C8: KAS KELUAR | D8: 1500000 | F8: Row Labels | G8: KAS KELUAR | H8: KAS MASUK
A9: 46037 | B9: NODE B 2 LOP JNP | C9: KAS MASUK | D9: 1500000 | F9: Jan | G9: 44779850 | H9: 47500000
A10: 46041 | B10: SEWA GUDANG & DP MANDOR JNP067 | C10: KAS KELUAR | D10: 10000000 | F10: Feb | G10: 10623850 | H10: 16000000
A11: 46041 | B11: NODE B 2 LOP JNP | C11: KAS MASUK | D11: 10000000 | F11: Mar | G11: 84743829 | H11: 86000000
A12: 46048 | B12: NODE B 2 LOP JNP | C12: KAS MASUK | D12: 15000000 | F12: Apr | G12: 110371600 | H12: 1.3307265e+08
A13: 46049 | B13: KASBON MANDOR | C13: KAS KELUAR | D13: 10000000 | F13: May | G13: 100816350 | H13: 91144488
A14: 46049 | B14: OPERASIONAL BENSIN DAN SEWA MOBIL | C14: KAS KELUAR | D14: 675000 | F14: Jun | G14: 20065314
A15: 46049 | B15: BAYARAN JOINTER | C15: KAS KELUAR | D15: 1500000 | F15: Jul | G15: 1464850 | H15: 1500000
A16: 46050 | B16: PEMBELIAN PIPA KONDUIT | C16: KAS KELUAR | D16: 300000 | F16: Aug | G16: 4964850 | H16: 4919261
A17: 46052 | B17: PEMBAYARAN JOINTER | C17: KAS KELUAR | D17: 500000 | F17: Grand Total | G17: 377830493 | H17: 3.801364e+08
A18: 46052 | B18: OPERASIONAL KE JNP | C18: KAS KELUAR | D18: 126000
A19: 46053 | B19: PELUNASAN MANDOR | C19: KAS KELUAR | D19: 19915000
A20: 46053 | B20: NODE B 2 LOP JNP | C20: KAS MASUK | D20: 21000000
A21: 46057 | B21: PEMBAYARAN JOINTER | C21: KAS KELUAR | D21: 500000
A22: 46059 | B22: OPERASIONAL KE JNP | C22: KAS KELUAR | D22: 500000
A23: 46060 | B23: PEMBAYARAN GAJI TEAM PROJECT | C23: KAS KELUAR | D23: 4000000
A24: 46060 | B24: NODE B 2 LOP JNP | C24: KAS MASUK | D24: 4000000
A25: 46061 | B25: OPERASIONAL | C25: KAS KELUAR | D25: 200000
A26: 46062 | B26: PELUNASAN JOINTER | C26: KAS KELUAR | D26: 1000000
A27: 46063 | B27: SURVEY BLK065 | C27: KAS KELUAR | D27: 250000
A28: 46064 | B28: SURVEY BLK044 | C28: KAS KELUAR | D28: 250000
A29: 46071 | B29: PEMBAYARAN WIFI KANTOR PERIODE FEBRUARI | C29: KAS KELUAR | D29: 263850
... A112: 46126 | B112: DP PEKERJAAN LOP DESA MICO | C112: KAS KELUAR | D112: 6000000
A113: 46126 | B113: JPP 4 LOP | C113: KAS MASUK | D113: =31241895+23156288 -> 54398183
A114: 46127 | B114: PINJAMAN DANA UTK HEM SATU SAMA | C114: KAS KELUAR | D114: 100000
A115: 46127 | B115: PINJAMAN DANA UTK HEM SATU SAMA | C115: KAS KELUAR | D115: 50000
A116: 46127 | B116: PINJAMAN DANA UTK HEM SATU SAMA | C116: KAS KELUAR | D116: 25000
A117: 46128 | B117: KASBON MANDOR | C117: KAS KELUAR | D117: 1050000
A118: 46128 | B118: PINJAMAN DANA UTK HEM SATU SAMA | C118: KAS KELUAR | D118: 900000
A119: 46128 | B119: SEWA KENDARAAN | C119: KAS KELUAR | D119: 350000
A120: 46128 | B120: BBM | C120: KAS KELUAR | D120: 200000
A121: 46128 | B121: GANTI RUGI MOBIL | C121: KAS KELUAR | D121: 300000
A122: 46128 | B122: KONSUMSI | C122: KAS KELUAR | D122: 112000
...

Sheet PV
A1: =TODAY() -> 46274 | B1: =TEXT(TODAY(),"dddd") -> Wednesday
A3: Sum of NILAI | D3: Row Labels | E3: Sum of NILAI | H3: Row Labels | I3: Sum of NILAI
A4: 759615840 | D4: Jan | E4: 75946550 | H4: WO#234 SILANGGA_KARENPIA_PL - TOMBOLO_PAO_AG | I4: 35425510
D5: Feb | E5: 149414980 | H5: BLK044 | I5: 36184890
A6: Count of NAMA PEKERJAAN | D6: Mar | E6: 452210100 | H6: WTP192 | I6: 60330170
A7: 28 | D7: Apr | E7: 12815440 | H7: JNP067 | I7: 61083710
D8: May | E8: 60330170 | H8: R5 MKS WTP PT3 MD 1650 CORAWALIE | I8: 79695390
A9: Count of NAMA PEKERJAAN | D9: Jul | E9: 8898600 | H9: R5 MKS WTP PT3 MD PATTIRO RIOLO | I9: 141171910
A10: 8 | D10: Grand Total | E10: 759615840 | H10: R5 MKS WTP PT3 MD DESA MICO | I10: 145297850
H11: Grand Total | I11: 559189430
A13: Row Labels | B13: Sum of CATATAN KAS
A14: KAS MASUK | B14: 3.817364e+08 | D14: Row Labels | E14: Sum of NILAI | H14: Sum of CATATAN KAS | I14: Column Labels
A15: Grand Total | B15: 3.817364e+08 | D15: DONE INSTALL 100% | E15: 0.011714606 | H15: Row Labels | I15: KAS MASUK | J15: Grand Total
D16: DROP | E16: 0.24026632 | H16: Jan | I16: 47500000 | J16: 47500000
A17: Row Labels | B17: Sum of NILAI | D17: MENUNGGU BOQ UT | E17: 0.072180169 | H17: Feb | I17: 16000000 | J17: 16000000
A18: BAST | B18: 75946550 | D18: MENUNGGU JADWAL UT | E18: 0.35415853 | H18: Mar | I18: 86000000 | J18: 86000000
A19: Grand Total | B19: 75946550 | D19: UJI TERIMA | E19: 0.079421948 | H19: Apr | I19: 1.3307265e+08 | J19: 1.3307265e+08
D20: REKON MATERIAL | E20: 0.14227822 | H20: May | I20: 91144488 | J20: 91144488
B21: =B18/A4 -> 0.099980208 | D21: BAST | E21: 0.099980208 | H21: Jul | I21: 1500000 | J21: 1500000
D22: Grand Total | E22: 1 | H22: Aug | I22: 4919261 | J22: 4919261
H23: Sep | I23: 1600000 | J23: 1600000
H24: Grand Total | I24: 3.817364e+08 | J24: 3.817364e+08

Sheet DATA SP
A1: NO | B1: JENIS PEKERJAAN | C1: NAMA PEKERJAAN | D1: NO SP | E1: TANGGAL | F1: NILAI | G1: KETERANGAN
A2: 1 | B2: NODE-B | C2: PENGADAAN DAN PEMASANGAN PEKERJAAN NODE-B JNP037 JNP067 WITEL MAKASSAR | D2: 4400047956/HK.810/TA-370002/01.2026 | E2: 46045 | F2: =SUM('DATA LOP'!H2:H3) -> 75946550 | G2: VERIFIKASI REGIONAL
A3: 2 | B3: NODE-B | C3: PENGADAAN DAN PEMASANGAN PEKERJAAN NODE-B 8 LOP BRANCH MAKASSAR | D3: 4400048812/HK.810/TA-370002/03.2026 | E3: 46090 | F3: =SUM('DATA LOP'!H4:H11) -> 149414980 | G3: MENUNGGU BOQ UT
A4: 3 | B4: NODE-B | C4: PENGADAAN DAN PEMASANGAN PEKERJAAN NODE-B 6 LOP BRANCH MAKASSAR | D4: 4200040829/HK.810/TA-370002/04.2026 | E4: 46132 | F4: =SUM('DATA LOP'!H12:H17) -> 19403690 | G4: MENUNGGU BOQ UT
A5: 4 | B5: MITRATEL | C5: PENGADAAN DAN PEMASANGAN PEKERJAAN MITRATEL WO#234 BRANCH MAKASSAR | D5: 1032/HK-810/TA.0207/04-2026 | E5: 46136 | F5: ='DATA LOP'!H23 -> 35425510 | G5: MENUNGGU BOQ UT
A6: 5 | B6: NODE-B | C6: PENGADAAN DAN PEMASANGAN PEKERJAAN NODE-B 1 LOP WTP192 BRANCH MAKASSAR | D6: 4400050084/HK.810/TA-370002/05.2026 | E6: 46150 | F6: ='DATA LOP'!H18 -> 60330170 | G6: MENUNGGU JADWAL UT
A7: 6 | B7: JPP MD | C7: PENGADAAN DAN PEMASANGAN PEKERJAAN JPP 4 LOP WITEL MAKASSAR | D7: 4400050203/HK.810/TA-370002/05.2026 | E7: 46161 | F7: =SUM('DATA LOP'!H19:H22) -> 383651594 | G7: PROGRES DOKUMEN CT/UT
A8: 7 | B8: HEM | C8: PENGADAAN DAN PEMASANGAN PEKERJAAN HEM 4 LOP BRANCH MAKASSAR | D8: 4400050523/HK.810/TA-370002/06.2026 | E8: 46183 | F8: =SUM('DATA LOP'!H24:H27) -> 14682170 | G8: MENUNGGU JADWAL UT
A9: 8 | B9: NODE-B | C9: PENGADAAN DAN PEMASANGAN PEKERJAAN NODE B 2 LOP BRANCH MAKASSAR | D9: NOT AVAILABLE | E9: NOT AVAILABLE | F9: 8898600 | G9: DONE INSTALL 100%

Sheet DATA LOP
A1: NO | B1: KATEGORI | C1: NAMA LOP | D1: TANGGAL SHARE ORDER | E1: KETERANGAN | F1: NILAI | G1: SURVEY | H1: DRM | I1: NAMA PEKERJAAN | J1: PO | K1: PRESENTASI PROJECT
A2: 1 | B2: NODE-B | C2: JNP037 | D2: 46031 | E2: BAST | F2: 14862840 | G2: 46032 | H2: 14862840 | I2: PENGADAAN DAN PEMASANGAN PEKERJAAN NODE-B JNP037 JNP067 WITEL MAKASSAR | J2: =VLOOKUP(Table1_1[[#This Row],[NAMA PEKERJAAN]],'DATA SP'!$C$2:$G$8,2,0) -> 4400047956/HK.810/TA-370002/01.2026 | K2: =IFERROR(IF(AND(E2="PROGRES LAPANGAN"),"20%",IF(AND(E2="DONE INSTALL 100%"),"40%",IF(AND(E2="MENUNGGU JADWAL UT"),50%,IF(AND(E2="PROGRES DOKUMEN CT/UT"),"60%",IF(AND(E2="UJI TERIMA"),"65%",IF(AND(E2="MENUNGGU BOQ UT"),"70%",IF(AND(E2="REKON MATERIAL"),"75%",IF(AND(E2="VERIFIKASI AREA"),"80%",IF(AND(E2="VERIFIKASI REGIONAL"),"85%",IF(AND(E2="BAST"),"90%",IF(AND(E2="INVOICE"),"100","0%"))))))))))),"") -> 90% | N2: SURVEY | O2: HEM
A3: 2 | B3: NODE-B | C3: JNP067 | D3: 46031 | E3: BAST | F3: 61083710 | G3: 46032 | H3: 61083710 | I3: PENGADAAN DAN PEMASANGAN PEKERJAAN NODE-B JNP037 JNP067 WITEL MAKASSAR | J3: =VLOOKUP(Table1_1[[#This Row],[NAMA PEKERJAAN]],'DATA SP'!$C$2:$G$8,2,0) -> 4400047956/HK.810/TA-370002/01.2026 | K3: =IFERROR(IF(AND(E3="PROGRES LAPANGAN"),"20%",IF(AND(E3="DONE INSTALL 100%"),"40%",IF(AND(E3="MENUNGGU JADWAL UT"),50%,IF(AND(E3="PROGRES DOKUMEN CT/UT"),"60%",IF(AND(E3="UJI TERIMA"),"65%",IF(AND(E3="MENUNGGU BOQ UT"),"70%",IF(AND(E3="REKON MATERIAL"),"75%",IF(AND(E3="VERIFIKASI AREA"),"80%",IF(AND(E3="VERIFIKASI REGIONAL"),"85%",IF(AND(E3="BAST"),"90%",IF(AND(E3="INVOICE"),"100","0%"))))))))))),"") -> 90% | N3: DROP | O3: MITRATEL
A4: 3 | B4: NODE-B | C4: BLK065 | D4: 46062 | E4: REKON MATERIAL | F4: 27112990 | G4: 46066 | H4: 27112990 | I4: PENGADAAN DAN PEMASANGAN PEKERJAAN NODE-B 8 LOP BRANCH MAKASSAR | J4: =VLOOKUP(Table1_1[[#This Row],[NAMA PEKERJAAN]],'DATA SP'!$C$2:$G$8,2,0) -> 4400048812/HK.810/TA-370002/03.2026 | K4: =IFERROR(IF(AND(E4="PROGRES LAPANGAN"),"20%",IF(AND(E4="DONE INSTALL 100%"),"40%",IF(AND(E4="MENUNGGU JADWAL UT"),50%,IF(AND(E4="PROGRES DOKUMEN CT/UT"),"60%",IF(AND(E4="UJI TERIMA"),"65%",IF(AND(E4="MENUNGGU BOQ UT"),"70%",IF(AND(E4="REKON MATERIAL"),"75%",IF(AND(E4="VERIFIKASI AREA"),"80%",IF(AND(E4="VERIFIKASI REGIONAL"),"85%",IF(AND(E4="BAST"),"90%",IF(AND(E4="INVOICE"),"100","0%"))))))))))),"") -> 75% | N4: PROGRES LAPANGAN | O4: NODE-B
A5: 4 | B5: NODE-B | C5: BLK044 | D5: 46062 | E5: REKON MATERIAL | F5: 36184890 | G5: 46066 | H5: 36184890 | I5: PENGADAAN DAN PEMASANGAN PEKERJAAN NODE-B 8 LOP BRANCH MAKASSAR | J5: =VLOOKUP(Table1_1[[#This Row],[NAMA PEKERJAAN]],'DATA SP'!$C$2:$G$8,2,0) -> 4400048812/HK.810/TA-370002/03.2026 | K5: =IFERROR(IF(AND(E5="PROGRES LAPANGAN"),"20%",IF(AND(E5="DONE INSTALL 100%"),"40%",IF(AND(E5="MENUNGGU JADWAL UT"),50%,IF(AND(E5="PROGRES DOKUMEN CT/UT"),"60%",IF(AND(E5="UJI TERIMA"),"65%",IF(AND(E5="MENUNGGU BOQ UT"),"70%",IF(AND(E5="REKON MATERIAL"),"75%",IF(AND(E5="VERIFIKASI AREA"),"80%",IF(AND(E5="VERIFIKASI REGIONAL"),"85%",IF(AND(E5="BAST"),"90%",IF(AND(E5="INVOICE"),"100","0%"))))))))))),"") -> 75% | N5: DONE INSTALL 100% | O5: JPP MD
A6: 5 | B6: NODE-B | C6: UPD708 | D6: 46071 | E6: DROP | F6: 570590 | G6: 46071 | H6: 570590 | I6: PENGADAAN DAN PEMASANGAN PEKERJAAN NODE-B 8 LOP BRANCH MAKASSAR | J6: =VLOOKUP(Table1_1[[#This Row],[NAMA PEKERJAAN]],'DATA SP'!$C$2:$G$8,2,0) -> 4400048812/HK.810/TA-370002/03.2026 | K6: =IFERROR(IF(AND(E6="PROGRES LAPANGAN"),"20%",IF(AND(E6="DONE INSTALL 100%"),"40%",IF(AND(E6="MENUNGGU JADWAL UT"),50%,IF(AND(E6="PROGRES DOKUMEN CT/UT"),"60%",IF(AND(E6="UJI TERIMA"),"65%",IF(AND(E6="MENUNGGU BOQ UT"),"70%",IF(AND(E6="REKON MATERIAL"),"75%",IF(AND(E6="VERIFIKASI AREA"),"80%",IF(AND(E6="VERIFIKASI REGIONAL"),"85%",IF(AND(E6="BAST"),"90%",IF(AND(E6="INVOICE"),"100","0%"))))))))))),"") -> 0% | N6: MENUNGGU JADWAL UT
A7: 6 | B7: NODE-B | C7: UPD707 | D7: 46071 | E7: REKON MATERIAL | F7: 6955430 | G7: 46071 | H7: 6955430 | I7: PENGADAAN DAN PEMASANGAN PEKERJAAN NODE-B 8 LOP BRANCH MAKASSAR | J7: =VLOOKUP(Table1_1[[#This Row],[NAMA PEKERJAAN]],'DATA SP'!$C$2:$G$8,2,0) -> 4400048812/HK.810/TA-370002/03.2026 | K7: =IFERROR(IF(AND(E7="PROGRES LAPANGAN"),"20%",IF(AND(E7="DONE INSTALL 100%"),"40%",IF(AND(E7="MENUNGGU JADWAL UT"),50%,IF(AND(E7="PROGRES DOKUMEN CT/UT"),"60%",IF(AND(E7="UJI TERIMA"),"65%",IF(AND(E7="MENUNGGU BOQ UT"),"70%",IF(AND(E7="REKON MATERIAL"),"75%",IF(AND(E7="VERIFIKASI AREA"),"80%",IF(AND(E7="VERIFIKASI REGIONAL"),"85%",IF(AND(E7="BAST"),"90%",IF(AND(E7="INVOICE"),"100","0%"))))))))))),"") -> 75% | N7: PROGRES DOKUMEN CT/UT
A8: 7 | B8: NODE-B | C8: UPD718 | D8: 46071 | E8: REKON MATERIAL | F8: 5579410 | G8: 46071 | H8: 5579410 | I8: PENGADAAN DAN PEMASANGAN PEKERJAAN NODE-B 8 LOP BRANCH MAKASSAR | J8: =VLOOKUP(Table1_1[[#This Row],[NAMA PEKERJAAN]],'DATA SP'!$C$2:$G$8,2,0) -> 4400048812/HK.810/TA-370002/03.2026 | K8: =IFERROR(IF(AND(E8="PROGRES LAPANGAN"),"20%",IF(AND(E8="DONE INSTALL 100%"),"40%",IF(AND(E8="MENUNGGU JADWAL UT"),50%,IF(AND(E8="PROGRES DOKUMEN CT/UT"),"60%",IF(AND(E8="UJI TERIMA"),"65%",IF(AND(E8="MENUNGGU BOQ UT"),"70%",IF(AND(E8="REKON MATERIAL"),"75%",IF(AND(E8="VERIFIKASI AREA"),"80%",IF(AND(E8="VERIFIKASI REGIONAL"),"85%",IF(AND(E8="BAST"),"90%",IF(AND(E8="INVOICE"),"100","0%"))))))))))),"") -> 75% | N8: MENUNGGU BOQ UT
A9: 8 | B9: NODE-B | C9: MRS202 | D9: 46055 | E9: REKON MATERIAL | F9: 32244070 | G9: 46060 | H9: 32244070 | I9: PENGADAAN DAN PEMASANGAN PEKERJAAN NODE-B 8 LOP BRANCH MAKASSAR | J9: =VLOOKUP(Table1_1[[#This Row],[NAMA PEKERJAAN]],'DATA SP'!$C$2:$G$8,2,0) -> 4400048812/HK.810/TA-370002/03.2026 | K9: =IFERROR(IF(AND(E9="PROGRES LAPANGAN"),"20%",IF(AND(E9="DONE INSTALL 100%"),"40%",IF(AND(E9="MENUNGGU JADWAL UT"),50%,IF(AND(E9="PROGRES DOKUMEN CT/UT"),"60%",IF(AND(E9="UJI TERIMA"),"65%",IF(AND(E9="MENUNGGU BOQ UT"),"70%",IF(AND(E9="REKON MATERIAL"),"75%",IF(AND(E9="VERIFIKASI AREA"),"80%",IF(AND(E9="VERIFIKASI REGIONAL"),"85%",IF(AND(E9="BAST"),"90%",IF(AND(E9="INVOICE"),"100","0%"))))))))))),"") -> 75% | N9: UJI TERIMA
A10: 9 | B10: NODE-B | C10: SNS230 | D10: 46058 | E10: DROP | F10: 6346650 | G10: 46063 | H10: 6346650 | I10: PENGADAAN DAN PEMASANGAN PEKERJAAN NODE-B 8 LOP BRANCH MAKASSAR | J10: =VLOOKUP(Table1_1[[#This Row],[NAMA PEKERJAAN]],'DATA SP'!$C$2:$G$8,2,0) -> 4400048812/HK.810/TA-370002/03.2026 | K10: =IFERROR(IF(AND(E10="PROGRES LAPANGAN"),"20%",IF(AND(E10="DONE INSTALL 100%"),"40%",IF(AND(E10="MENUNGGU JADWAL UT"),50%,IF(AND(E10="PROGRES DOKUMEN CT/UT"),"60%",IF(AND(E10="UJI TERIMA"),"65%",IF(AND(E10="MENUNGGU BOQ UT"),"70%",IF(AND(E10="REKON MATERIAL"),"75%",IF(AND(E10="VERIFIKASI AREA"),"80%",IF(AND(E10="VERIFIKASI REGIONAL"),"85%",IF(AND(E10="BAST"),"90%",IF(AND(E10="INVOICE"),"100","0%"))))))))))),"") -> 0% | N10: REKON MATERIAL
A11: 10 | B11: NODE-B | C11: SNS231 | D11: 46058 | E11: DROP | F11: 34420950 | G11: 46063 | H11: 34420950 | I11: PENGADAAN DAN PEMASANGAN PEKERJAAN NODE-B 8 LOP BRANCH MAKASSAR | J11: =VLOOKUP(Table1_1[[#This Row],[NAMA PEKERJAAN]],'DATA SP'!$C$2:$G$8,2,0) -> 4400048812/HK.810/TA-370002/03.2026 | K11: =IFERROR(IF(AND(E11="PROGRES LAPANGAN"),"20%",IF(AND(E11="DONE INSTALL 100%"),"40%",IF(AND(E11="MENUNGGU JADWAL UT"),50%,IF(AND(E11="PROGRES DOKUMEN CT/UT"),"60%",IF(AND(E11="UJI TERIMA"),"65%",IF(AND(E11="MENUNGGU BOQ UT"),"70%",IF(AND(E11="REKON MATERIAL"),"75%",IF(AND(E11="VERIFIKASI AREA"),"80%",IF(AND(E11="VERIFIKASI REGIONAL"),"85%",IF(AND(E11="BAST"),"90%",IF(AND(E11="INVOICE"),"100","0%"))))))))))),"") -> 0% | N11: VERIFIKASI AREA
A12: 11 | B12: NODE-B | C12: UPD739 | D12: 46083 | E12: MENUNGGU BOQ UT | F12: 5275380 | G12: 46110 | H12: 5275380 | I12: PENGADAAN DAN PEMASANGAN PEKERJAAN NODE-B 6 LOP BRANCH MAKASSAR | J12: =VLOOKUP(Table1_1[[#This Row],[NAMA PEKERJAAN]],'DATA SP'!$C$2:$G$8,2,0) -> 4200040829/HK.810/TA-370002/04.2026 | K12: =IFERROR(IF(AND(E12="PROGRES LAPANGAN"),"20%",IF(AND(E12="DONE INSTALL 100%"),"40%",IF(AND(E12="MENUNGGU JADWAL UT"),50%,IF(AND(E12="PROGRES DOKUMEN CT/UT"),"60%",IF(AND(E12="UJI TERIMA"),"65%",IF(AND(E12="MENUNGGU BOQ UT"),"70%",IF(AND(E12="REKON MATERIAL"),"75%",IF(AND(E12="VERIFIKASI AREA"),"80%",IF(AND(E12="VERIFIKASI REGIONAL"),"85%",IF(AND(E12="BAST"),"90%",IF(AND(E12="INVOICE"),"100","0%"))))))))))),"") -> 70% | N12: VERIFIKASI REGIONAL
A13: 12 | B13: NODE-B | C13: UPD740 | D13: 46083 | E13: MENUNGGU BOQ UT | F13: 680200 | G13: 46110 | H13: 680200 | I13: PENGADAAN DAN PEMASANGAN PEKERJAAN NODE-B 6 LOP BRANCH MAKASSAR | J13: =VLOOKUP(Table1_1[[#This Row],[NAMA PEKERJAAN]],'DATA SP'!$C$2:$G$8,2,0) -> 4200040829/HK.810/TA-370002/04.2026 | K13: =IFERROR(IF(AND(E13="PROGRES LAPANGAN"),"20%",IF(AND(E13="DONE INSTALL 100%"),"40%",IF(AND(E13="MENUNGGU JADWAL UT"),50%,IF(AND(E13="PROGRES DOKUMEN CT/UT"),"60%",IF(AND(E13="UJI TERIMA"),"65%",IF(AND(E13="MENUNGGU BOQ UT"),"70%",IF(AND(E13="REKON MATERIAL"),"75%",IF(AND(E13="VERIFIKASI AREA"),"80%",IF(AND(E13="VERIFIKASI REGIONAL"),"85%",IF(AND(E13="BAST"),"90%",IF(AND(E13="INVOICE"),"100","0%"))))))))))),"") -> 70% | N13: BAST
A14: 13 | B14: NODE-B | C14: UPD736 | D14: 46086 | E14: MENUNGGU BOQ UT | F14: 3834770 | G14: 46064 | H14: 3834770 | I14: PENGADAAN DAN PEMASANGAN PEKERJAAN NODE-B 6 LOP BRANCH MAKASSAR | J14: =VLOOKUP(Table1_1[[#This Row],[NAMA PEKERJAAN]],'DATA SP'!$C$2:$G$8,2,0) -> 4200040829/HK.810/TA-370002/04.2026 | K14: =IFERROR(IF(AND(E14="PROGRES LAPANGAN"),"20%",IF(AND(E14="DONE INSTALL 100%"),"40%",IF(AND(E14="MENUNGGU JADWAL UT"),50%,IF(AND(E14="PROGRES DOKUMEN CT/UT"),"60%",IF(AND(E14="UJI TERIMA"),"65%",IF(AND(E14="MENUNGGU BOQ UT"),"70%",IF(AND(E14="REKON MATERIAL"),"75%",IF(AND(E14="VERIFIKASI AREA"),"80%",IF(AND(E14="VERIFIKASI REGIONAL"),"85%",IF(AND(E14="BAST"),"90%",IF(AND(E14="INVOICE"),"100","0%"))))))))))),"") -> 70% | N14: INVOICED
A15: 14 | B15: NODE-B | C15: UPD699 | D15: 46086 | E15: MENUNGGU BOQ UT | F15: 437590 | G15: 46110 | H15: 437590 | I15: PENGADAAN DAN PEMASANGAN PEKERJAAN NODE-B 6 LOP BRANCH MAKASSAR | J15: =VLOOKUP(Table1_1[[#This Row],[NAMA PEKERJAAN]],'DATA SP'!$C$2:$G$8,2,0) -> 4200040829/HK.810/TA-370002/04.2026 | K15: =IFERROR(IF(AND(E15="PROGRES LAPANGAN"),"20%",IF(AND(E15="DONE INSTALL 100%"),"40%",IF(AND(E15="MENUNGGU JADWAL UT"),50%,IF(AND(E15="PROGRES DOKUMEN CT/UT"),"60%",IF(AND(E15="UJI TERIMA"),"65%",IF(AND(E15="MENUNGGU BOQ UT"),"70%",IF(AND(E15="REKON MATERIAL"),"75%",IF(AND(E15="VERIFIKASI AREA"),"80%",IF(AND(E15="VERIFIKASI REGIONAL"),"85%",IF(AND(E15="BAST"),"90%",IF(AND(E15="INVOICE"),"100","0%"))))))))))),"") -> 70% | N15: CLOSED
A16: 15 | B16: NODE-B | C16: UPD710 | D16: 46086 | E16: MENUNGGU BOQ UT | F16: 1917070 | G16: 46064 | H16: 1917070 | I16: PENGADAAN DAN PEMASANGAN PEKERJAAN NODE-B 6 LOP BRANCH MAKASSAR | J16: =VLOOKUP(Table1_1[[#This Row],[NAMA PEKERJAAN]],'DATA SP'!$C$2:$G$8,2,0) -> 4200040829/HK.810/TA-370002/04.2026 | K16: =IFERROR(IF(AND(E16="PROGRES LAPANGAN"),"20%",IF(AND(E16="DONE INSTALL 100%"),"40%",IF(AND(E16="MENUNGGU JADWAL UT"),50%,IF(AND(E16="PROGRES DOKUMEN CT/UT"),"60%",IF(AND(E16="UJI TERIMA"),"65%",IF(AND(E16="MENUNGGU BOQ UT"),"70%",IF(AND(E16="REKON MATERIAL"),"75%",IF(AND(E16="VERIFIKASI AREA"),"80%",IF(AND(E16="VERIFIKASI REGIONAL"),"85%",IF(AND(E16="BAST"),"90%",IF(AND(E16="INVOICE"),"100","0%"))))))))))),"") -> 70%
A17: 16 | B17: NODE-B | C17: UPD663 | D17: 46097 | E17: MENUNGGU BOQ UT | F17: 7258680 | G17: 46097 | H17: 7258680 | I17: PENGADAAN DAN PEMASANGAN PEKERJAAN NODE-B 1 LOP WTP192 BRANCH MAKASSAR | J17: =VLOOKUP(Table1_1[[#This Row],[NAMA PEKERJAAN]],'DATA SP'!$C$2:$G$8,2,0) -> 4400050084/HK.810/TA-370002/05.2026 | K17: =IFERROR(IF(AND(E17="PROGRES LAPANGAN"),"20%",IF(AND(E17="DONE INSTALL 100%"),"40%",IF(AND(E17="MENUNGGU JADWAL UT"),50%,IF(AND(E17="PROGRES DOKUMEN CT/UT"),"60%",IF(AND(E17="UJI TERIMA"),"65%",IF(AND(E17="MENUNGGU BOQ UT"),"70%",IF(AND(E17="REKON MATERIAL"),"75%",IF(AND(E17="VERIFIKASI AREA"),"80%",IF(AND(E17="VERIFIKASI REGIONAL"),"85%",IF(AND(E17="BAST"),"90%",IF(AND(E17="INVOICE"),"100","0%"))))))))))),"") -> 70%
A18: 17 | B18: NODE-B | C18: WTP192 | D18: 46150 | E18: UJI TERIMA | F18: 60330170 | G18: 46132 | H18: 60330170 | I18: PENGADAAN DAN PEMASANGAN PEKERJAAN JPP 4 LOP WITEL MAKASSAR | J18: =VLOOKUP(Table1_1[[#This Row],[NAMA PEKERJAAN]],'DATA SP'!$C$2:$G$8,2,0) -> 4400050203/HK.810/TA-370002/05.2026 | K18: =IFERROR(IF(AND(E18="PROGRES LAPANGAN"),"20%",IF(AND(E18="DONE INSTALL 100%"),"40%",IF(AND(E18="MENUNGGU JADWAL UT"),50%,IF(AND(E18="PROGRES DOKUMEN CT/UT"),"60%",IF(AND(E18="UJI TERIMA"),"65%",IF(AND(E18="MENUNGGU BOQ UT"),"70%",IF(AND(E18="REKON MATERIAL"),"75%",IF(AND(E18="VERIFIKASI AREA"),"80%",IF(AND(E18="VERIFIKASI REGIONAL"),"85%",IF(AND(E18="BAST"),"90%",IF(AND(E18="INVOICE"),"100","0%"))))))))))),"") -> 65%
A19: 18 | B19: JPP MD | C19: R5 MKS WTP PT3 MD 1650 CORAWALIE | D19: 46092 | E19: MENUNGGU JADWAL UT | F19: 79695390 | G19: 46107 | H19: 76276790 | I19: PENGADAAN DAN PEMASANGAN PEKERJAAN JPP 4 LOP WITEL MAKASSAR | J19: =VLOOKUP(Table1_1[[#This Row],[NAMA PEKERJAAN]],'DATA SP'!$C$2:$G$8,2,0) -> 4400050203/HK.810/TA-370002/05.2026 | K19: =IFERROR(IF(AND(E19="PROGRES LAPANGAN"),"20%",IF(AND(E19="DONE INSTALL 100%"),"40%",IF(AND(E19="MENUNGGU JADWAL UT"),50%,IF(AND(E19="PROGRES DOKUMEN CT/UT"),"60%",IF(AND(E19="UJI TERIMA"),"65%",IF(AND(E19="MENUNGGU BOQ UT"),"70%",IF(AND(E19="REKON MATERIAL"),"75%",IF(AND(E19="VERIFIKASI AREA"),"80%",IF(AND(E19="VERIFIKASI REGIONAL"),"85%",IF(AND(E19="BAST"),"90%",IF(AND(E19="INVOICE"),"100","0%"))))))))))),"") -> 0.5
A20: 19 | B20: JPP MD | C20: R5 MKS WTP PT3 MD DESA MICO | D20: 46092 | E20: MENUNGGU JADWAL UT | F20: 145297850 | G20: 46108 | H20: 135548650 | I20: PENGADAAN DAN PEMASANGAN PEKERJAAN JPP 4 LOP WITEL MAKASSAR | J20: =VLOOKUP(Table1_1[[#This Row],[NAMA PEKERJAAN]],'DATA SP'!$C$2:$G$8,2,0) -> 4400050203/HK.810/TA-370002/05.2026 | K20: =IFERROR(IF(AND(E20="PROGRES LAPANGAN"),"20%",IF(AND(E20="DONE INSTALL 100%"),"40%",IF(AND(E20="MENUNGGU JADWAL UT"),50%,IF(AND(E20="PROGRES DOKUMEN CT/UT"),"60%",IF(AND(E20="UJI TERIMA"),"65%",IF(AND(E20="MENUNGGU BOQ UT"),"70%",IF(AND(E20="REKON MATERIAL"),"75%",IF(AND(E20="VERIFIKASI AREA"),"80%",IF(AND(E20="VERIFIKASI REGIONAL"),"85%",IF(AND(E20="BAST"),"90%",IF(AND(E20="INVOICE"),"100","0%"))))))))))),"") -> 0.5
A21: 20 | B21: JPP MD | C21: R5 MKS WTP PT3 MD Bone jln Biru | D21: 46092 | E21: MENUNGGU JADWAL UT | F21: 31215750 | G21: 46108 | H21: 30700350 | I21: PENGADAAN DAN PEMASANGAN PEKERJAAN JPP 4 LOP WITEL MAKASSAR | J21: =VLOOKUP(Table1_1[[#This Row],[NAMA PEKERJAAN]],'DATA SP'!$C$2:$G$8,2,0) -> 4400050203/HK.810/TA-370002/05.2026 | K21: =IFERROR(IF(AND(E21="PROGRES LAPANGAN"),"20%",IF(AND(E21="DONE INSTALL 100%"),"40%",IF(AND(E21="MENUNGGU JADWAL UT"),50%,IF(AND(E21="PROGRES DOKUMEN CT/UT"),"60%",IF(AND(E21="UJI TERIMA"),"65%",IF(AND(E21="MENUNGGU BOQ UT"),"70%",IF(AND(E21="REKON MATERIAL"),"75%",IF(AND(E21="VERIFIKASI AREA"),"80%",IF(AND(E21="VERIFIKASI REGIONAL"),"85%",IF(AND(E21="BAST"),"90%",IF(AND(E21="INVOICE"),"100","0%"))))))))))),"") -> 0.5
A22: 21 | B22: JPP MD | C22: R5 MKS WTP PT3 MD PATTIRO RIOLO | D22: 46092 | E22: DROP | F22: 141171910 | G22: 46106 | H22: 141125804 | I22: PENGADAAN DAN PEMASANGAN PEKERJAAN JPP 4 LOP WITEL MAKASSAR | J22: =VLOOKUP(Table1_1[[#This Row],[NAMA PEKERJAAN]],'DATA SP'!$C$2:$G$8,2,0) -> 4400050203/HK.810/TA-370002/05.2026 | K22: =IFERROR(IF(AND(E22="PROGRES LAPANGAN"),"20%",IF(AND(E22="DONE INSTALL 100%"),"40%",IF(AND(E22="MENUNGGU JADWAL UT"),50%,IF(AND(E22="PROGRES DOKUMEN CT/UT"),"60%",IF(AND(E22="UJI TERIMA"),"65%",IF(AND(E22="MENUNGGU BOQ UT"),"70%",IF(AND(E22="REKON MATERIAL"),"75%",IF(AND(E22="VERIFIKASI AREA"),"80%",IF(AND(E22="VERIFIKASI REGIONAL"),"85%",IF(AND(E22="BAST"),"90%",IF(AND(E22="INVOICE"),"100","0%"))))))))))),"") -> 0%
A23: 22 | B23: MITRATEL | C23: WO#234 SILANGGA_KARENPIA_PL - TOMBOLO_PAO_AG | D23: 46107 | E23: MENUNGGU BOQ UT | F23: 35425510 | G23: 46110 | H23: 35425510 | I23: PENGADAAN DAN PEMASANGAN PEKERJAAN MITRATEL WO#234 BRANCH MAKASSAR | J23: =VLOOKUP(Table1_1[[#This Row],[NAMA PEKERJAAN]],'DATA SP'!$C$2:$G$8,2,0) -> 1032/HK-810/TA.0207/04-2026 | K23: =IFERROR(IF(AND(E23="PROGRES LAPANGAN"),"20%",IF(AND(E23="DONE INSTALL 100%"),"40%",IF(AND(E23="MENUNGGU JADWAL UT"),50%,IF(AND(E23="PROGRES DOKUMEN CT/UT"),"60%",IF(AND(E23="UJI TERIMA"),"65%",IF(AND(E23="MENUNGGU BOQ UT"),"70%",IF(AND(E23="REKON MATERIAL"),"75%",IF(AND(E23="VERIFIKASI AREA"),"80%",IF(AND(E23="VERIFIKASI REGIONAL"),"85%",IF(AND(E23="BAST"),"90%",IF(AND(E23="INVOICE"),"100","0%"))))))))))),"") -> 70%
A24: 23 | B24: HEM | C24: HEM SATU SAMA JAYA ABADI | D24: 46123 | E24: MENUNGGU JADWAL UT | F24: 2729700 | G24: 46123 | H24: 2288500 | I24: PENGADAAN DAN PEMASANGAN PEKERJAAN HEM 4 LOP BRANCH MAKASSAR | J24: =VLOOKUP(Table1_1[[#This Row],[NAMA PEKERJAAN]],'DATA SP'!$C$2:$G$8,2,0) -> 4400050523/HK.810/TA-370002/06.2026 | K24: =IFERROR(IF(AND(E24="PROGRES LAPANGAN"),"20%",IF(AND(E24="DONE INSTALL 100%"),"40%",IF(AND(E24="MENUNGGU JADWAL UT"),50%,IF(AND(E24="PROGRES DOKUMEN CT/UT"),"60%",IF(AND(E24="UJI TERIMA"),"65%",IF(AND(E24="MENUNGGU BOQ UT"),"70%",IF(AND(E24="REKON MATERIAL"),"75%",IF(AND(E24="VERIFIKASI AREA"),"80%",IF(AND(E24="VERIFIKASI REGIONAL"),"85%",IF(AND(E24="BAST"),"90%",IF(AND(E24="INVOICE"),"100","0%"))))))))))),"") -> 0.5
A25: 24 | B25: HEM | C25: Site Perwakilan Prov. Sulawesi Selatan (BPK Provinsi Sulawesi Selatan) | D25: 46123 | E25: MENUNGGU JADWAL UT | F25: 7238240 | G25: 46123 | H25: 6956400 | I25: PENGADAAN DAN PEMASANGAN PEKERJAAN HEM 4 LOP BRANCH MAKASSAR | J25: =VLOOKUP(Table1_1[[#This Row],[NAMA PEKERJAAN]],'DATA SP'!$C$2:$G$8,2,0) -> 4400050523/HK.810/TA-370002/06.2026 | K25: =IFERROR(IF(AND(E25="PROGRES LAPANGAN"),"20%",IF(AND(E25="DONE INSTALL 100%"),"40%",IF(AND(E25="MENUNGGU JADWAL UT"),50%,IF(AND(E25="PROGRES DOKUMEN CT/UT"),"60%",IF(AND(E25="UJI TERIMA"),"65%",IF(AND(E25="MENUNGGU BOQ UT"),"70%",IF(AND(E25="REKON MATERIAL"),"75%",IF(AND(E25="VERIFIKASI AREA"),"80%",IF(AND(E25="VERIFIKASI REGIONAL"),"85%",IF(AND(E25="BAST"),"90%",IF(AND(E25="INVOICE"),"100","0%"))))))))))),"") -> 0.5
A26: 25 | B26: HEM | C26: PT2-BLK-KUA UJUNG BULU | D26: 46136 | E26: MENUNGGU JADWAL UT | F26: 278300 | G26: 46136 | H26: 593230 | I26: PENGADAAN DAN PEMASANGAN PEKERJAAN HEM 4 LOP BRANCH MAKASSAR | J26: =VLOOKUP(Table1_1[[#This Row],[NAMA PEKERJAAN]],'DATA SP'!$C$2:$G$8,2,0) -> 4400050523/HK.810/TA-370002/06.2026 | K26: =IFERROR(IF(AND(E26="PROGRES LAPANGAN"),"20%",IF(AND(E26="DONE INSTALL 100%"),"40%",IF(AND(E26="MENUNGGU JADWAL UT"),50%,IF(AND(E26="PROGRES DOKUMEN CT/UT"),"60%",IF(AND(E26="UJI TERIMA"),"65%",IF(AND(E26="MENUNGGU BOQ UT"),"70%",IF(AND(E26="REKON MATERIAL"),"75%",IF(AND(E26="VERIFIKASI AREA"),"80%",IF(AND(E26="VERIFIKASI REGIONAL"),"85%",IF(AND(E26="BAST"),"90%",IF(AND(E26="INVOICE"),"100","0%"))))))))))),"") -> 0.5
A27: 26 | B27: HEM | C27: Site Balai Diklat Gowa (BDPKN Gowa) | D27: 46141 | E27: MENUNGGU JADWAL UT | F27: 2569200 | G27: 46141 | H27: 4844040 | I27: PENGADAAN DAN PEMASANGAN PEKERJAAN HEM 4 LOP BRANCH MAKASSAR | J27: =VLOOKUP(Table1_1[[#This Row],[NAMA PEKERJAAN]],'DATA SP'!$C$2:$G$8,2,0) -> 4400050523/HK.810/TA-370002/06.2026 | K27: =IFERROR(IF(AND(E27="PROGRES LAPANGAN"),"20%",IF(AND(E27="DONE INSTALL 100%"),"40%",IF(AND(E27="MENUNGGU JADWAL UT"),50%,IF(AND(E27="PROGRES DOKUMEN CT/UT"),"60%",IF(AND(E27="UJI TERIMA"),"65%",IF(AND(E27="MENUNGGU BOQ UT"),"70%",IF(AND(E27="REKON MATERIAL"),"75%",IF(AND(E27="VERIFIKASI AREA"),"80%",IF(AND(E27="VERIFIKASI REGIONAL"),"85%",IF(AND(E27="BAST"),"90%",IF(AND(E27="INVOICE"),"100","0%"))))))))))),"") -> 0.5
A28: 27 | B28: NODE-B | C28: UPD770 | D28: 46230 | E28: DONE INSTALL 100% | F28: 4226100 | G28: 46230 | H28: 4226100 | I28: PENGADAAN DAN PEMASANGAN PEKERJAAN NODE B 2 LOP BRANCH MAKASSAR | J28: NOT AVAILABLE | K28: =IFERROR(IF(AND(E28="PROGRES LAPANGAN"),"20%",IF(AND(E28="DONE INSTALL 100%"),"40%",IF(AND(E28="MENUNGGU JADWAL UT"),50%,IF(AND(E28="PROGRES DOKUMEN CT/UT"),"60%",IF(AND(E28="UJI TERIMA"),"65%",IF(AND(E28="MENUNGGU BOQ UT"),"70%",IF(AND(E28="REKON MATERIAL"),"75%",IF(AND(E28="VERIFIKASI AREA"),"80%",IF(AND(E28="VERIFIKASI REGIONAL"),"85%",IF(AND(E28="BAST"),"90%",IF(AND(E28="INVOICE"),"100","0%"))))))))))),"") -> 40%
A29: 28 | B29: NODE-B | C29: UPD860 | D29: 46230 | E29: DONE INSTALL 100% | F29: 4672500 | G29: 46230 | H29: 4672500 | I29: PENGADAAN DAN PEMASANGAN PEKERJAAN NODE B 2 LOP BRANCH MAKASSAR | J29: NOT AVAILABLE | K29: =IFERROR(IF(AND(E29="PROGRES LAPANGAN"),"20%",IF(AND(E29="DONE INSTALL 100%"),"40%",IF(AND(E29="MENUNGGU JADWAL UT"),50%,IF(AND(E29="PROGRES DOKUMEN CT/UT"),"60%",IF(AND(E29="UJI TERIMA"),"65%",IF(AND(E29="MENUNGGU BOQ UT"),"70%",IF(AND(E29="REKON MATERIAL"),"75%",IF(AND(E29="VERIFIKASI AREA"),"80%",IF(AND(E29="VERIFIKASI REGIONAL"),"85%",IF(AND(E29="BAST"),"90%",IF(AND(E29="INVOICE"),"100","0%"))))))))))),"") -> 40%

Sheet DASHBORAD PM
L1: NO | M1: JENIS PEKERJAAN | N1: NAMA PEKERJAAN | O1: NO SP | P1: TANGGAL | Q1: NILAI BOQ | R1: BUDGET | S1: REALISASI ANGGARAN | T1: PRESENTASI PENGGUNAAN | U1: SISA BUDGET
L2: 1 | M2: NODE-B | N2: NODE-B JNP037 JNP067 WITEL MAKASSAR | O2: 4400047956/HK.810/TA-370002/01.2026 | P2: 46045 | Q2: 79279120 | R2: =Table3__22[[#This Row],[NILAI BOQ]]*0.7 -> 55664399 | S2: 53000000 | T2: =Table3__22[[#This Row],[REALISASI ANGGARAN]]/Table3__22[[#This Row],[BUDGET ]] -> 0.9521346 | U2: =Table3__22[[#This Row],[BUDGET ]]-Table3__22[[#This Row],[REALISASI ANGGARAN]] -> 2664399 | BF2: Row Labels | BG2: Sum of NILAI BOQ | BJ2: Row Labels | BK2: Sum of REALISASI ANGGARAN | BL2: Sum of BUDGET | BO2: Row Labels | BP2: Sum of PRESENTASI PENGGUNAAN | BR2: Row Labels | BS2: Sum of REALISASI ANGGARAN | BT2: Sum of BUDGET
L3: 2 | M3: NODE-B | N3: NODE-B 8 LOP BRANCH MAKASSAR | O3: 4400048812/HK.810/TA-370002/03.2026 | P3: 46090 | Q3: 110798180 | R3: =Table3__22[[#This Row],[NILAI BOQ]]*0.7 -> 77558726 | S3: 72000000 | T3: =Table3__22[[#This Row],[REALISASI ANGGARAN]]/Table3__22[[#This Row],[BUDGET ]] -> 0.92832881 | U3: =Table3__22[[#This Row],[BUDGET ]]-Table3__22[[#This Row],[REALISASI ANGGARAN]] -> 5558726 | BF3: NODE-B JNP037 JNP067 WITEL MAKASSAR | BG3: 79279120 | BJ3: HEM | BK3: 8463750 | BL3: 10277519 | BO3: JPP 4 LOP WITEL MAKASSAR | BP3: 1.0596693 | BR3: Jan | BS3: 53000000 | BT3: 55495384
L4: 3 | M4: NODE-B | N4: NODE-B 6 LOP BRANCH MAKASSAR | O4: 4200040829/HK.810/TA-370002/04.2026 | P4: 46132 | Q4: 23353370 | R4: =Table3__22[[#This Row],[NILAI BOQ]]*0.7 -> 16347359 | S4: 15100000 | T4: =Table3__22[[#This Row],[REALISASI ANGGARAN]]/Table3__22[[#This Row],[BUDGET ]] -> 0.9236966 | U4: =Table3__22[[#This Row],[BUDGET ]]-Table3__22[[#This Row],[REALISASI ANGGARAN]] -> 1247359 | BF4: NODE-B 8 LOP BRANCH MAKASSAR | BG4: 110798180 | BJ4: JPP MD | BK4: 168065942 | BL4: 158602255 | BO4: MITRATEL WO#234 BRANCH MAKASSAR | BP4: 0.98552526 | BR4: Mar | BS4: 72000000 | BT4: 77558726
L5: 4 | M5: MITRATEL | N5: MITRATEL WO#234 BRANCH MAKASSAR | O5: 1032/HK-810/TA.0207/04-2026 | P5: 46136 | Q5: 32245530 | R5: =Table3__22[[#This Row],[NILAI BOQ]]*0.7 -> 22571871 | S5: 22245149 | T5: =Table3__22[[#This Row],[REALISASI ANGGARAN]]/Table3__22[[#This Row],[BUDGET ]] -> 0.98552526 | U5: =Table3__22[[#This Row],[BUDGET ]]-Table3__22[[#This Row],[REALISASI ANGGARAN]] -> 326722 | BF5: NODE-B 6 LOP BRANCH MAKASSAR | BG5: 23353370 | BJ5: MITRATEL | BK5: 22245149 | BL5: 22571871 | BO5: NODE-B JNP037 JNP067 WITEL MAKASSAR | BP5: 0.95503439 | BR5: Apr | BS5: 37345149 | BT5: 38919230
L6: 5 | M6: NODE-B | N6: NODE-B 1 LOP WTP192 BRANCH MAKASSAR | O6: 4400050084/HK.810/TA-370002/05.2026 | P6: 46150 | Q6: 63640718 | R6: =Table3__22[[#This Row],[NILAI BOQ]]*0.7 -> 44548503 | S6: 37942298 | T6: =Table3__22[[#This Row],[REALISASI ANGGARAN]]/Table3__22[[#This Row],[BUDGET ]] -> 0.8517076 | U6: =Table3__22[[#This Row],[BUDGET ]]-Table3__22[[#This Row],[REALISASI ANGGARAN]] -> 6606204.5 | BF6: MITRATEL WO#234 BRANCH MAKASSAR | BG6: 32245530 | BJ6: NODE-B | BK6: 1.8296156e+08 | BL6: 2.0017899e+08 | BO6: NODE-B 8 LOP BRANCH MAKASSAR | BP6: 0.92832881 | BR6: May | BS6: 2.0600824e+08 | BT6: 2.0315076e+08
L7: 6 | M7: JPP MD | N7: JPP 4 LOP WITEL MAKASSAR | O7: 4400050203/HK.810/TA-370002/05.2026 | P7: 46161 | Q7: 226574650 | R7: =Table3__22[[#This Row],[NILAI BOQ]]*0.7 -> 158602255 | S7: 168065942 | T7: =Table3__22[[#This Row],[REALISASI ANGGARAN]]/Table3__22[[#This Row],[BUDGET ]] -> 1.0596693 | U7: =Table3__22[[#This Row],[BUDGET ]]-Table3__22[[#This Row],[REALISASI ANGGARAN]] -> -9463687 | BF7: NODE-B 1 LOP WTP192 BRANCH MAKASSAR | BG7: 63640718 | BJ7: Grand Total | BK7: 3.817364e+08 | BL7: 3.9163064e+08 | BO7: NODE-B 6 LOP BRANCH MAKASSAR | BP7: 0.9236966 | BR7: Jun | BS7: 8463750 | BT7: 10277519
L8: 7 | M8: HEM | N8: HEM 4 LOP BRANCH MAKASSAR | O8: 4400050523/HK.810/TA-370002/06.2026 | P8: 46183 | Q8: 14682170 | R8: =Table3__22[[#This Row],[NILAI BOQ]]*0.7 -> 10277519 | S8: 8463750 | T8: =Table3__22[[#This Row],[REALISASI ANGGARAN]]/Table3__22[[#This Row],[BUDGET ]] -> 0.82352073 | U8: =Table3__22[[#This Row],[BUDGET ]]-Table3__22[[#This Row],[REALISASI ANGGARAN]] -> 1813769 | BF8: JPP 4 LOP WITEL MAKASSAR | BG8: 226574650 | BO8: NODE-B 1 LOP WTP192 BRANCH MAKASSAR | BP8: 0.8517076 | BR8: Aug | BS8: 4919261 | BT8: 6229020
L9: 8 | M9: NODE-B | N9: NODE B 2 LOP BRANCH MAKASSAR | O9: NOT AVAILABLE | P9: 46264 | Q9: 8898600 | R9: =Table3__22[[#This Row],[NILAI BOQ]]*0.7 -> 6229020 | S9: 4919261 | T9: =Table3__22[[#This Row],[REALISASI ANGGARAN]]/Table3__22[[#This Row],[BUDGET ]] -> 0.78973273 | U9: =Table3__22[[#This Row],[BUDGET ]]-Table3__22[[#This Row],[REALISASI ANGGARAN]] -> 1309759 | BF9: HEM 4 LOP BRANCH MAKASSAR | BG9: 14682170 | BO9: HEM 4 LOP BRANCH MAKASSAR | BP9: 0.82352073
BF10: NODE B 2 LOP BRANCH MAKASSAR | BG10: 8898600 | BO10: NODE B 2 LOP BRANCH MAKASSAR | BP10: 0.78973273
BF11: Grand Total | BG11: 559472338 | BO11: Grand Total | BP11: 7.3172154
BF16: Row Labels | BG16: Sum of NILAI BOQ | BJ16: Row Labels | BK16: Sum of SISA BUDGET | BN16: Sum of SISA BUDGET
BF17: NODE-B JNP037 JNP067 WITEL MAKASSAR | BG17: 0.14170338 | BJ17: NODE-B JNP037 JNP067 WITEL MAKASSAR | BK17: 2495384 | BN17: 9894236.5
BF18: NODE-B 8 LOP BRANCH MAKASSAR | BG18: 0.1980405 | BJ18: NODE-B 8 LOP BRANCH MAKASSAR | BK18: 5558726
BF19: NODE-B 6 LOP BRANCH MAKASSAR | BG19: 0.041741778 | BJ19: NODE-B 6 LOP BRANCH MAKASSAR | BK19: 1247359
B20: ` | BF20: MITRATEL WO#234 BRANCH MAKASSAR | BG20: 0.057635611 | BJ20: MITRATEL WO#234 BRANCH MAKASSAR | BK20: 326722
BF21: NODE-B 1 LOP WTP192 BRANCH MAKASSAR | BG21: 0.11375132 | BJ21: NODE-B 1 LOP WTP192 BRANCH MAKASSAR | BK21: 6606204.5
BF22: JPP 4 LOP WITEL MAKASSAR | BG22: 0.40497918 | BJ22: JPP 4 LOP WITEL MAKASSAR | BK22: -9463687
BF23: HEM 4 LOP BRANCH MAKASSAR | BG23: 0.026242888 | BJ23: HEM 4 LOP BRANCH MAKASSAR | BK23: 1813769
BF24: NODE B 2 LOP BRANCH MAKASSAR | BG24: 0.015905344 | BJ24: NODE B 2 LOP BRANCH MAKASSAR | BK24: 1309759
BF25: Grand Total | BG25: 1 | BJ25: Grand Total | BK25: 9894236.5
BF27: Sum of NILAI BOQ
BF28: 559472338 | BJ28: Sum of BUDGET
BJ29: 3.9163064e+08
BJ32: =BJ36/BJ29 -> 0.9747358
BJ35: Sum of REALISASI ANGGARAN
BJ36: 3.817364e+08

Sheet BUDGETING & REALISATION
A1: NO | B1: JENIS PEKERJAAN | C1: NAMA PEKERJAAN | D1: NO SP | E1: TANGGAL | F1: NILAI BOQ | G1: BUDGET | H1: REALISASI ANGGARAN | I1: PRESENTASI PENGGUNAAN | J1: SISA BUDGET | K1: STATUS BUDGET
A2: 1 | B2: NODE-B | C2: PENGADAAN DAN PEMASANGAN PEKERJAAN NODE-B JNP037 JNP067 WITEL MAKASSAR | D2: 4400047956/HK.810/TA-370002/01.2026 | E2: 46045 | F2: 79520570 | G2: =Table3__22[[#This Row],[NILAI BOQ]]*0.7 -> 55664399 | H2: 53000000 | I2: =Table3__22[[#This Row],[REALISASI ANGGARAN]]/Table3__22[[#This Row],[BUDGET ]] -> 0.9521346 | J2: =Table3__22[[#This Row],[BUDGET ]]-Table3__22[[#This Row],[REALISASI ANGGARAN]] -> 2664399 | K2: =IFERROR(IF(Table3__22[[#This Row],[REALISASI ANGGARAN]]<Table3__22[[#This Row],[BUDGET ]],"BUDGET SURPLUS","OVER BUDGET"),"") -> BUDGET SURPLUS
A3: 2 | B3: NODE-B | C3: PENGADAAN DAN PEMASANGAN PEKERJAAN NODE-B 8 LOP BRANCH MAKASSAR | D3: 4400048812/HK.810/TA-370002/03.2026 | E3: 46090 | F3: 110798180 | G3: =Table3__22[[#This Row],[NILAI BOQ]]*0.7 -> 77558726 | H3: 72000000 | I3: =Table3__22[[#This Row],[REALISASI ANGGARAN]]/Table3__22[[#This Row],[BUDGET ]] -> 0.92832881 | J3: =Table3__22[[#This Row],[BUDGET ]]-Table3__22[[#This Row],[REALISASI ANGGARAN]] -> 5558726 | K3: =IFERROR(IF(Table3__22[[#This Row],[REALISASI ANGGARAN]]<Table3__22[[#This Row],[BUDGET ]],"BUDGET SURPLUS","OVER BUDGET"),"") -> BUDGET SURPLUS
A4: 3 | B4: NODE-B | C4: PENGADAAN DAN PEMASANGAN PEKERJAAN NODE-B 6 LOP BRANCH MAKASSAR | D4: 4200040829/HK.810/TA-370002/04.2026 | E4: 46132 | F4: 23353370 | G4: =Table3__22[[#This Row],[NILAI BOQ]]*0.7 -> 16347359 | H4: 15100000 | I4: =Table3__22[[#This Row],[REALISASI ANGGARAN]]/Table3__22[[#This Row],[BUDGET ]] -> 0.9236966 | J4: =Table3__22[[#This Row],[BUDGET ]]-Table3__22[[#This Row],[REALISASI ANGGARAN]] -> 1247359 | K4: =IFERROR(IF(Table3__22[[#This Row],[REALISASI ANGGARAN]]<Table3__22[[#This Row],[BUDGET ]],"BUDGET SURPLUS","OVER BUDGET"),"") -> BUDGET SURPLUS
A5: 4 | B5: MITRATEL | C5: PENGADAAN DAN PEMASANGAN PEKERJAAN MITRATEL WO#234 BRANCH MAKASSAR | D5: 1032/HK-810/TA.0207/04-2026 | E5: 46136 | F5: 32245530 | G5: =Table3__22[[#This Row],[NILAI BOQ]]*0.7 -> 22571871 | H5: 22245149 | I5: =Table3__22[[#This Row],[REALISASI ANGGARAN]]/Table3__22[[#This Row],[BUDGET ]] -> 0.98552526 | J5: =Table3__22[[#This Row],[BUDGET ]]-Table3__22[[#This Row],[REALISASI ANGGARAN]] -> 326722 | K5: =IFERROR(IF(Table3__22[[#This Row],[REALISASI ANGGARAN]]<Table3__22[[#This Row],[BUDGET ]],"BUDGET SURPLUS","OVER BUDGET"),"") -> BUDGET SURPLUS
A6: 5 | B6: NODE-B | C6: PENGADAAN DAN PEMASANGAN PEKERJAAN NODE-B 1 LOP WTP192 BRANCH MAKASSAR | D6: 4400050084/HK.810/TA-370002/05.2026 | E6: 46150 | F6: 63640718 | G6: =Table3__22[[#This Row],[NILAI BOQ]]*0.7 -> 44548503 | H6: 37942298 | I6: =Table3__22[[#This Row],[REALISASI ANGGARAN]]/Table3__22[[#This Row],[BUDGET ]] -> 0.8517076 | J6: =Table3__22[[#This Row],[BUDGET ]]-Table3__22[[#This Row],[REALISASI ANGGARAN]] -> 6606204.5 | K6: =IFERROR(IF(Table3__22[[#This Row],[REALISASI ANGGARAN]]<Table3__22[[#This Row],[BUDGET ]],"BUDGET SURPLUS","OVER BUDGET"),"") -> BUDGET SURPLUS
A7: 6 | B7: JPP MD | C7: PENGADAAN DAN PEMASANGAN PEKERJAAN JPP 4 LOP WITEL MAKASSAR | D7: 4400050203/HK.810/TA-370002/05.2026 | E7: 46161 | F7: 226574650 | G7: =Table3__22[[#This Row],[NILAI BOQ]]*0.7 -> 158602255 | H7: 168065942 | I7: =Table3__22[[#This Row],[REALISASI ANGGARAN]]/Table3__22[[#This Row],[BUDGET ]] -> 1.0596693 | J7: =Table3__22[[#This Row],[BUDGET ]]-Table3__22[[#This Row],[REALISASI ANGGARAN]] -> -9463687 | K7: =IFERROR(IF(Table3__22[[#This Row],[REALISASI ANGGARAN]]<Table3__22[[#This Row],[BUDGET ]],"BUDGET SURPLUS","OVER BUDGET"),"") -> OVER BUDGET
A8: 7 | B8: HEM | C8: PENGADAAN DAN PEMASANGAN PEKERJAAN HEM 4 LOP BRANCH MAKASSAR | D8: 4400050523/HK.810/TA-370002/06.2026 | E8: 46183 | F8: =SUM('DATA LOP'!H24:H27) -> 14682170 | G8: =Table3__22[[#This Row],[NILAI BOQ]]*0.7 -> 10277519 | H8: 8463750 | I8: =Table3__22[[#This Row],[REALISASI ANGGARAN]]/Table3__22[[#This Row],[BUDGET ]] -> 0.82352073 | J8: =Table3__22[[#This Row],[BUDGET ]]-Table3__22[[#This Row],[REALISASI ANGGARAN]] -> 1813769 | K8: =IFERROR(IF(Table3__22[[#This Row],[REALISASI ANGGARAN]]<Table3__22[[#This Row],[BUDGET ]],"BUDGET SURPLUS","OVER BUDGET"),"") -> BUDGET SURPLUS
A9: 8 | B9: NODE-B | C9: PENGADAAN DAN PEMASANGAN PEKERJAAN NODE B 2 LOP BRANCH MAKASSAR | D9: NOT AVAILABLE | E9: 46264 | F9: 8898600 | G9: =Table3__22[[#This Row],[NILAI BOQ]]*0.7 -> 6229020 | H9: 4919261 | I9: =Table3__22[[#This Row],[REALISASI ANGGARAN]]/Table3__22[[#This Row],[BUDGET ]] -> 0.78973273 | J9: =Table3__22[[#This Row],[BUDGET ]]-Table3__22[[#This Row],[REALISASI ANGGARAN]] -> 1309759 | K9: =IFERROR(IF(Table3__22[[#This Row],[REALISASI ANGGARAN]]<Table3__22[[#This Row],[BUDGET ]],"BUDGET SURPLUS","OVER BUDGET"),"") -> BUDGET SURPLUS
C10: TOTAL | F10: =SUBTOTAL(109,Table3__22[NILAI BOQ]) -> 559713788 | G10: =SUBTOTAL(109,Table3__22[[BUDGET ]]) -> 3.9179965e+08 | H10: =SUBTOTAL(109,Table3__22[REALISASI ANGGARAN]) -> 3.817364e+08 | J10: =SUBTOTAL(109,Table3__22[SISA BUDGET]) -> 10063251 | K10: =Table3__22[[#Totals],[BUDGET ]]-Table3__22[[#Totals],[REALISASI ANGGARAN]] -> 10063252
K11: =Table3__22[[#Totals],[STATUS BUDGET]]/Table3__22[[#Totals],[BUDGET ]] -> 0.025684687
